<?xml version="1.0" ?>
<robot name="ur5">
    <link name="base">
        <inertial>
            <mass value="0.0"/>
            <inertia ixx="1.0" ixy="1.0" ixz="1.0"
                     iyy="0.0" iyz="0.0" izz="0.0"/>
        </inertial>
    </link>

    <joint name="base_joint" type="fixed">
        <origin xyz="0 0 0" rpy="0 0 1.570796"/>
        <parent link="base"/>
        <child link="base_link"/>
        <axis xyz="0 -1 0"/>
    </joint>

    <link name="base_link">
        <visual>
            <geometry>
                <mesh filename="package://meshes/visual/base.obj"/>
            </geometry>
            <material name="LightGrey">
                <color rgba="0.7 0.7 0.7 1.0"/>
            </material>
        </visual>
        <collision>
            <geometry>
                <mesh filename="package://meshes/collision/base.stl"/>
            </geometry>
        </collision>
        <inertial>
            <mass value="0.0"/>
            <origin rpy="0 0 0" xyz="0.0 0.0 0.0"/>
            <inertia ixx="0.00443333156" ixy="0.0" ixz="0.0"
                     iyy="0.00443333156" iyz="0.0" izz="0.0072"/>
        </inertial>
    </link>

    <joint name="shoulder_pan_joint" type="revolute">
        <parent link="base_link"/>
        <child link="shoulder_link"/>
        <origin rpy="0.0 0.0 3.14" xyz="0.0 0.0 0.089159"/>
        <axis xyz="0 0 1"/>
        <limit effort="300.0" lower="-6.28318530718" upper="6.28318530718"
               velocity="3.15"/>
        <dynamics damping="0.5" friction="0.0"/>
    </joint>

    <link name="shoulder_link">
        <visual>
            <geometry>
                <mesh filename="package://meshes/visual/shoulder.obj"/>
            </geometry>
            <material name="LightGrey">
                <color rgba="0.7 0.7 0.7 1.0"/>
            </material>
        </visual>
        <collision>
            <geometry>
                <mesh filename="package://meshes/collision/shoulder.stl"/>
            </geometry>
        </collision>
        <inertial>
            <mass value="3.7"/>
            <origin rpy="0 0 0" xyz="0.0 0.0 0.5"/>
            <inertia ixx="0.010267495893" ixy="0.0" ixz="0.0"
                     iyy="0.010267495893" iyz="0.0" izz="0.00666"/>
        </inertial>
    </link>

    <joint name="shoulder_lift_joint" type="revolute">
        <parent link="shoulder_link"/>
        <child link="upper_arm_link"/>
        <origin rpy="0.0 0.0 0.0" xyz="0.0 0.13585 0.0"/>
        <axis xyz="0 1 0"/>
        <limit effort="300.0" lower="-2.35619449019" upper="2.35619449019"
               velocity="3.15"/>
        <dynamics damping="0.5" friction="0.0"/>
    </joint>

    <link name="upper_arm_link">
        <visual>
            <geometry>
                <mesh filename="package://meshes/visual/upperarm.obj"/>
            </geometry>
            <material name="LightGrey">
                <color rgba="0.7 0.7 0.7 1.0"/>
            </material>
        </visual>
        <collision>
            <geometry>
                <mesh filename="package://meshes/collision/upperarm.stl"/>
            </geometry>
        </collision>
        <inertial>
            <mass value="8.393"/>
            <origin rpy="0 0 0" xyz="0.0 0.0 0.28"/>
            <inertia ixx="0.22689067591" ixy="0.0" ixz="0.0"
                     iyy="0.22689067591" iyz="0.0" izz="0.0151074"/>
        </inertial>
    </link>

    <joint name="elbow_joint" type="revolute">
        <parent link="upper_arm_link"/>
        <child link="forearm_link"/>
        <origin rpy="0.0 0.0 0.0" xyz="0.0 -0.1197 0.425"/>
        <axis xyz="0 1 0"/>
        <limit effort="300.0" lower="-3.14159265359" upper="3.14159265359"
               velocity="3.15"/>
        <dynamics damping="0.5" friction="0.0"/>
    </joint>

    <link name="forearm_link">
        <visual>
            <geometry>
                <mesh filename="package://meshes/visual/forearm.obj"/>
            </geometry>
            <material name="LightGrey">
                <color rgba="0.7 0.7 0.7 1.0"/>
            </material>
        </visual>
        <collision>
            <geometry>
                <mesh filename="package://meshes/collision/forearm.stl"/>
            </geometry>
        </collision>
        <inertial>
            <mass value="2.275"/>
            <origin rpy="0 0 0" xyz="0.0 0.0 0.25"/>
            <inertia ixx="0.049443313556" ixy="0.0" ixz="0.0"
                     iyy="0.049443313556" iyz="0.0" izz="0.004095"/>
        </inertial>
    </link>

    <joint name="wrist_1_joint" type="revolute">
        <parent link="forearm_link"/>
        <child link="wrist_1_link"/>
        <origin rpy="0.0 0.0 0.0" xyz="0.0 0.0 0.39225"/>
        <axis xyz="0 1 0"/>
        <limit effort="300.0" lower="-2.35619449019" upper="2.35619449019"
               velocity="3.2"/>
        <dynamics damping="0.5" friction="0.0"/>
    </joint>

    <link name="wrist_1_link">
        <visual>

            <geometry>
                <mesh filename="package://meshes/visual/wrist1.obj"/>
            </geometry>
            <material name="LightGrey">
                <color rgba="0.7 0.7 0.7 1.0"/>
            </material>
        </visual>
        <collision>
            <geometry>
                <mesh filename="package://meshes/collision/wrist1.stl"/>
            </geometry>
        </collision>
        <inertial>
            <mass value="1.219"/>
            <origin rpy="0 0 0" xyz="0.0 0.0 0.0"/>
            <inertia ixx="0.111172755531" ixy="0.0" ixz="0.0"
                     iyy="0.111172755531" iyz="0.0" izz="0.21942"/>
        </inertial>
    </link>

    <joint name="wrist_2_joint" type="revolute">
        <parent link="wrist_1_link"/>
        <child link="wrist_2_link"/>
        <origin rpy="0.0 0.0 0.0" xyz="0.0 0.093 0.0"/>
        <axis xyz="0 0 1"/>
        <limit effort="300.0" lower="-6.28318530718" upper="6.28318530718"
               velocity="3.2"/>
        <dynamics damping="0.5" friction="0.0"/>
    </joint>

    <link name="wrist_2_link">
        <visual>
            <geometry>
                <mesh filename="package://meshes/visual/wrist2.obj"/>
            </geometry>
            <material name="LightGrey">
                <color rgba="0.7 0.7 0.7 1.0"/>
            </material>
        </visual>
        <collision>
            <geometry>
                <mesh filename="package://meshes/collision/wrist2.stl"/>
            </geometry>
        </collision>
        <inertial>
            <mass value="1.219"/>
            <origin rpy="0 0 0" xyz="0.0 0.0 0.0"/>
            <inertia ixx="0.111172755531" ixy="0.0" ixz="0.0"
                     iyy="0.111172755531" iyz="0.0" izz="0.21942"/>
        </inertial>
    </link>

    <joint name="wrist_3_joint" type="revolute">
        <parent link="wrist_2_link"/>
        <child link="wrist_3_link"/>
        <origin rpy="0.0 0.0 0.0" xyz="0.0 0.0 0.09465"/>
        <axis xyz="0 1 0"/>
        <limit effort="300.0" lower="-6.28318530718" upper="6.28318530718"
               velocity="3.2"/>
        <dynamics damping="0.5" friction="0.0"/>
    </joint>

    <link name="wrist_3_link">
        <visual>
            <geometry>
                <mesh filename="package://meshes/visual/wrist3.obj"/>
            </geometry>
            <material name="LightGrey">
                <color rgba="0.7 0.7 0.7 1.0"/>
            </material>
        </visual>
        <collision>
            <geometry>
                <mesh filename="package://meshes/collision/wrist3.stl"/>
            </geometry>
        </collision>
        <inertial>
            <mass value="0.1879"/>
            <origin rpy="0 0 0" xyz="0.0 0.0 0.0"/>
            <inertia ixx="0.0171364731454" ixy="0.0" ixz="0.0"
                     iyy="0.0171364731454" iyz="0.0" izz="0.033822"/>
        </inertial>
    </link>


    ## Robotiq 85 Gripper

    <joint name="arm_gripper_joint" type="fixed">
        <parent link="wrist_3_link"/>
        <child link="robotiq_85_base_link"/>
        <origin rpy="-1.570796 3.141592 0.0" xyz="0.0 0.0823 0.0"/>
        <axis xyz="0 1 0"/>
    </joint>

    <link name="robotiq_85_base_link">
        <inertial>
            <origin xyz="0.00021987 -2.3546E-10 0.030163" rpy="0 0 0"/>
            <mass value="0.30915"/>
            <inertia ixx="0.00028972" ixy="-5.7879E-10" ixz="-1.8543E-06"
                     iyy="0.00030737" iyz="1.682E-12" izz="0.00019914"/>
        </inertial>
        <visual>
            <origin xyz="0 0 0" rpy="0 0 0"/>
            <geometry>
                <mesh filename="package://meshes/visual/robotiq_85_base_link_fine.STL"/>
            </geometry>
            <material name="red">
                <color rgba="1 0 0 1"/>
            </material>
        </visual>
        <collision>
            <origin xyz="0 0 0" rpy="0 0 0"/>
            <geometry>
                <mesh filename="package://meshes/collision/robotiq_85_base_link_coarse.STL"/>
            </geometry>
        </collision>
    </link>
    <link name="left_outer_knuckle">
        <inertial>
            <origin xyz="0.0178331863169983 3.68915177224286E-11 0.0021442477325704"
                    rpy="0 0 0"/>
            <mass value="0.00684838849434396"/>
            <inertia
                    ixx="2.66832029033166E-07"
                    ixy="1.66142314639824E-15"
                    ixz="1.45945633322873E-07"
                    iyy="1.3889233257419E-06"
                    iyz="2.82951161241588E-15"
                    izz="1.26603336914415E-06"/>
        </inertial>
        <visual>
            <origin xyz="0 0 0" rpy="0 0 0"/>
            <geometry>
                <mesh filename="package://meshes/visual/outer_knuckle_fine.STL"/>
            </geometry>
            <material name="green">
                <color rgba="0 1 0 1"/>
            </material>
        </visual>
        <collision>
            <origin xyz="0 0 0" rpy="0 0 0"/>
            <geometry>
                <mesh filename="package://meshes/collision/outer_knuckle_coarse.STL"/>
            </geometry>
        </collision>
    </link>
    <joint name="left_outer_knuckle_joint" type="revolute">
        <origin xyz="0.0306011444260539 0 0.0627920162695395"
                rpy="0 0 0"/>
        <parent link="robotiq_85_base_link"/>
        <child link="left_outer_knuckle"/>
        <axis xyz="0 -1 0"/>
        <limit lower="0" upper="0.725" velocity="2.0" effort="20"/>
    </joint>
    <link name="left_outer_finger">
        <inertial>
            <origin xyz="0.00131451599174296 2.88942057994543E-15 0.0215404163180413"
                    rpy="0 0 0"/>
            <mass value="0.0273093985570947"/>
            <inertia
                    ixx="8.51629628283022E-06"
                    ixy="2.58174336207405E-19"
                    ixz="3.83829504344079E-07"
                    iyy="6.9133328065108E-06"
                    iyz="-7.58589926143789E-19"
                    izz="2.25006832221981E-06"/>
        </inertial>
        <visual>
            <origin xyz="0 0 0" rpy="0 0 0"/>
            <geometry>
                <mesh filename="package://meshes/visual/outer_finger_fine.STL"/>
            </geometry>
            <material name="blue">
                <color rgba="0 0 1 1"/>
            </material>
        </visual>
        <collision>
            <origin xyz="0 0 0" rpy="0 0 0"/>
            <geometry>
                <mesh filename="package://meshes/collision/outer_finger_coarse.STL"/>
            </geometry>
        </collision>
    </link>

    <link name="left_inner_loop">
        <inertial>
            <mass value="0.0"/>
            <inertia ixx="1.0" ixy="1.0" ixz="1.0" iyy="0.0" iyz="0.0"
                     izz="0.0"/>
        </inertial>
    </link>

    <link name="left_outer_loop">
        <inertial>
            <mass value="0.0"/>
            <inertia ixx="1.0" ixy="1.0" ixz="1.0" iyy="0.0" iyz="0.0"
                     izz="0.0"/>
        </inertial>
    </link>

    <joint name="left_inner_finger_loop"
           type="fixed">
        <origin xyz="0.018 0 -0.0065" rpy="0 0 0"/>
        <parent link="left_inner_finger"/>
        <child link="left_inner_loop"/>
        <axis xyz="0 1 0"/>
        <limit lower="-6.28318530718" upper="6.28318530718"/>
    </joint>

    <joint name="left_outer_finger_loop" type="fixed">
        <origin xyz="0.003 0 0.0475" rpy="0 0 0"/>
        <parent link="left_outer_finger"/>
        <child link="left_outer_loop"/>
        <axis xyz="0 1 0"/>
    </joint>

    <joint name="left_outer_finger_joint" type="fixed">
        <origin xyz="0.0316910442266543 0 -0.00193396375724605"
                rpy="0 0 0"/>
        <parent link="left_outer_knuckle"/>
        <child link="left_outer_finger"/>
        <axis xyz="0 -1 0"/>
    </joint>
    <link name="left_inner_knuckle">
        <inertial>
            <origin xyz="0.017097546626628 -3.93808524389535E-10 0.0224918438201868"
                    rpy="0 0 0"/>
            <mass value="0.0110930853895903"/>
            <inertia ixx="4.23392770691541E-06"
                     ixy="5.748978936968E-15"
                     ixz="1.78855677119788E-06"
                     iyy="3.96548790524392E-06"
                     iyz="1.05464666369669E-14"
                     izz="3.24068002883007E-06"/>
        </inertial>
        <visual>
            <origin xyz="0 0 0" rpy="0 0 0"/>
            <geometry>
                <mesh filename="package://meshes/visual/inner_knuckle_fine.STL"/>
            </geometry>
            <material name="yellow">
                <color rgba="1 1 0 1"/>
            </material>
        </visual>
        <collision>
            <origin xyz="0 0 0" rpy="0 0 0"/>
            <geometry>
                <mesh filename="package://meshes/collision/inner_knuckle_coarse.STL"/>
            </geometry>
        </collision>
    </link>
    <joint name="left_inner_knuckle_joint" type="revolute">
        <origin xyz="0.0127000000001501 0 0.0693074999999639"
                rpy="0 0 0"/>
        <parent link="robotiq_85_base_link"/>
        <child link="left_inner_knuckle"/>
        <axis xyz="0 -1 0"/>
        <limit lower="0" upper="0.8757" velocity="2.0" effort="20"/>
    </joint>
    <link name="left_inner_finger">
        <inertial>
            <origin xyz="0.0060275613594574 -6.29183141465421E-15 0.00669925693133241"
                    rpy="0 0 0"/>
            <mass value="0.00724255346165745"/>
            <inertia
                    ixx="1.47824274053603E-06"
                    ixy="-3.94884463570303E-19"
                    ixz="-3.45268847648622E-07"
                    iyy="1.70064480838395E-06"
                    iyz="3.5059838910097E-19"
                    izz="4.77151336838364E-07"/>
        </inertial>
        <visual>
            <origin xyz="0 0 0"
                    rpy="0 0 0"/>
            <geometry>
                <mesh filename="package://meshes/visual/inner_finger_fine.STL"/>
            </geometry>
            <material name="magenta">
                <color rgba="1 0 1 1"/>
            </material>
        </visual>
        <collision>
            <origin xyz="0 0 0"
                    rpy="0 0 0"/>
            <geometry>
                <mesh filename="package://meshes/collision/inner_finger_coarse.STL"/>
            </geometry>
        </collision>
        <contact>
            <stiffness value="10000"/>
            <damping value="10"/>
                     <lateral_friction value="100.0"/>

        </contact>

    </link>
    <joint name="left_inner_finger_joint" type="revolute">
        <origin xyz="0.034585310861294 0 0.0454970193817975" rpy="0 0 0"/>
        <parent link="left_inner_knuckle"/>
        <child link="left_inner_finger"/>
        <axis xyz="0 -1 0"/>
        <limit lower="0" upper="0.8757" velocity="2.0" effort="20"/>
    </joint>

    <link name="right_inner_knuckle">
        <inertial>
            <origin xyz="0.0168606186773776 3.93808471820465E-10 0.0226699950793434"
                    rpy="0 0 0"/>
            <mass value="0.0110930853895903"/>
            <inertia ixx="4.27134775939882E-06"
                     ixy="-8.53568456728898E-15"
                     ixz="1.77774229944246E-06"
                     iyy="3.96548790524392E-06"
                     iyz="-8.45108024914164E-15"
                     izz="3.20325997634666E-06"/>
        </inertial>
        <visual>
            <origin xyz="0 0 0" rpy="0 0 0"/>
            <geometry>
                <mesh filename="package://meshes/visual/inner_knuckle_fine.STL"/>
            </geometry>
            <material name="yellow_light">
                <color rgba="1 1 0 .5"/>
            </material>
        </visual>
        <collision>
            <origin xyz="0 0 0" rpy="0 0 0"/>
            <geometry>
                <mesh filename="package://meshes/collision/inner_knuckle_coarse.STL"/>
            </geometry>
        </collision>
    </link>
    <joint name="right_inner_knuckle_joint" type="revolute">
        <origin xyz="-0.0126999999998499 0 0.0693075000000361"
                rpy="0 0 3.14159265358979"/>
        <parent link="robotiq_85_base_link"/>
        <child link="right_inner_knuckle"/>
        <axis xyz="0 -1 0"/>
        <limit lower="0" upper="0.8757" velocity="2.0" effort="20"/>
    </joint>
    <link name="right_inner_finger">
        <inertial>
            <origin xyz="0.00602756228812038 -6.47284509480176E-15 0.00669925609578108"
                    rpy="0 0 0"/>
            <mass value="0.00724255346165744"/>
            <inertia
                    ixx="1.47824283625957E-06"
                    ixy="-3.95952064019123E-19"
                    ixz="-3.45268708875543E-07"
                    iyy="1.70064480838394E-06"
                    iyz="3.55286507960029E-19"
                    izz="4.77151241114822E-07"/>
        </inertial>
        <visual>
            <origin xyz="0 0 0" rpy="0 0 0"/>
            <geometry>
                <mesh filename="package://meshes/visual/inner_finger_fine.STL"/>
            </geometry>
            <material name="magenta_light">
                <color rgba="1 0 1 .5"/>
            </material>
        </visual>
        <collision>
            <origin xyz="0 0 0"
                    rpy="0 0 0"/>
            <geometry>
                <mesh filename="package://meshes/collision/inner_finger_coarse.STL"/>
            </geometry>
        </collision>
        <contact>
            <stiffness value="10000"/>
            <damping value="10"/>
                     <lateral_friction value="100.0"/>

        </contact>

    </link>
    <joint name="right_inner_finger_joint" type="revolute">
        <origin xyz="0.0341060475457406 0 0.0458573878541688"
                rpy="0 0 0"/>
        <parent link="right_inner_knuckle"/>
        <child link="right_inner_finger"/>
        <axis xyz="0 -1 0"/>
        <limit lower="0" upper="0.8757" velocity="2.0" effort="20"/>
    </joint>
    <link name="right_outer_knuckle">
        <inertial>
            <origin xyz="0.0178097074051638 3.60493211424024E-11 0.00233123458346721"
                    rpy="0 0 0"/>
            <mass value="0.00684838849401352"/>
            <inertia
                    ixx="2.70004361573169E-07"
                    ixy="1.59579467624491E-15"
                    ixz="1.56396493788199E-07"
                    iyy="1.38892332558312E-06"
                    iyz="2.82357800318817E-15"
                    izz="1.26286103637978E-06"/>
        </inertial>
        <visual>
            <origin xyz="0 0 0" rpy="0 0 0"/>
            <geometry>
                <mesh filename="package://meshes/visual/outer_knuckle_fine.STL"/>
            </geometry>
            <material name="green_light">
                <color rgba="0 1 0 .5"/>
            </material>
        </visual>
        <collision>
            <origin xyz="0 0 0" rpy="0 0 0"/>
            <geometry>
                <mesh filename="package://meshes/collision/outer_knuckle_coarse.STL"/>
            </geometry>
        </collision>
    </link>
    <joint name="right_outer_knuckle_joint" type="revolute">
        <origin xyz="-0.0306011444258893 0 0.0627920162695395"
                rpy="0 0 3.14159265358979"/>
        <parent link="robotiq_85_base_link"/>
        <child link="right_outer_knuckle"/>
        <axis xyz="0 -1 0"/>
        <limit lower="0" upper="0.8757" velocity="2.0" effort="20"/>
    </joint>
    <link name="right_outer_finger">
        <inertial>
            <origin xyz="0.00108844269639009 -2.611488350845E-15 0.0215530225245502"
                    rpy="0 0 0"/>
            <mass value="0.0273093985570947"/>
            <inertia ixx="8.52366028592721E-06"
                     ixy="3.41683380899422E-19"
                     ixz="3.18003675694284E-07"
                     iyy="6.91333280651081E-06"
                     iyz="7.37726682706417E-19"
                     izz="2.24270431912283E-06"/>
        </inertial>
        <visual>
            <origin xyz="0 0 0" rpy="0 0 0"/>
            <geometry>
                <mesh filename="package://meshes/visual/outer_finger_fine.STL"/>
            </geometry>
            <material name="light_blue">
                <color rgba="0 0 1 .5"/>
            </material>
        </visual>
        <collision>
            <origin xyz="0 0 0"
                    rpy="0 0 0"/>
            <geometry>
                <mesh filename="package://meshes/collision/outer_finger_coarse.STL"/>
            </geometry>
        </collision>
    </link>
    <joint name="right_outer_finger_joint"
           type="fixed">
        <origin xyz="0.0317095909367246 0 -0.0016013564954687"
                rpy="0 0 0"/>
        <parent link="right_outer_knuckle"/>
        <child link="right_outer_finger"/>
        <axis xyz="0 -1 0"/>
    </joint>
    <link name="right_inner_loop">
        <inertial>
            <mass value="0.0"/>
            <inertia ixx="1.0" ixy="1.0" ixz="1.0"
                     iyy="0.0" iyz="0.0" izz="0.0"/>
        </inertial>
    </link>

    <link name="right_outer_loop">
        <inertial>
            <mass value="0.0"/>
            <inertia ixx="1.0" ixy="1.0" ixz="1.0"
                     iyy="0.0" iyz="0.0" izz="0.0"/>
        </inertial>
    </link>

    <joint name="right_inner_finger_loop"
           type="fixed">
        <origin xyz="0.018 0 -0.0065"
                rpy="0 0 0"/>
        <parent link="right_inner_finger"/>
        <child link="right_inner_loop"/>
        <axis xyz="0 -1 0"/>
        <limit lower="-6.28318530718" upper="6.28318530718"/>
    </joint>

    <joint name="right_outer_finger_loop"
           type="fixed">
        <origin xyz="0.003 0 0.0475"
                rpy="0 0 0"/>
        <parent link="right_outer_finger"/>
        <child link="right_outer_loop"/>
        <axis xyz="0 -1 0"/>
    </joint>

    <joint name="tcp" type="fixed">
        <parent link="robotiq_85_base_link"/>
        <child link="tcp"/>
        <origin rpy="0 0 -1.570796" xyz="0.0 0.0 0.15"/>
        <axis xyz="0 1 0"/>
    </joint>

    <link name="tcp">
        <inertial>
            <mass value="0.0"/>
            <inertia ixx="1.0" ixy="1.0" ixz="1.0" iyy="0.0" iyz="0.0"
                     izz="0.0"/>
        </inertial>
    </link>

</robot>


