<?xml version="1.0" ?>
<!-- ======================================================================= -->
<!-- | This document was autogenerated by xacro from lbr_iiwa.urdf.xacro   | -->
<!-- | Original xacro: https://github.com/rtkg/lbr_iiwa/archive/master.zip | -->
<!-- | EDITING THIS FILE BY HAND IS NOT RECOMMENDED                        | -->
<!-- | Changes (kohlhoff):                                                 | -->
<!-- |   * Removed gazebo tags.                                            | -->
<!-- |   * Removed unused materials.                                       | -->
<!-- |   * Made mesh paths relative.                                       | -->
<!-- |   * Removed material fields from collision segments.                | -->
<!-- |   * Removed the self_collision_checking segment.                    | -->
<!-- |   * Removed transmission segments, since they didn't match the      | -->
<!-- |     convention, will have to added back later.                      | -->
<!-- ======================================================================= -->
<!--LICENSE:                                                                 -->
<!--Copyright (c) 2015, Robert Krug & Todor Stoyanov, AASS Research Center,  -->
<!--Orebro University, Sweden                                                -->
<!--All rights reserved.                                                     -->
<!--                                                                         -->
<!--Redistribution and use in source and binary forms, with or without       -->
<!--modification, are permitted provided that the following conditions are   -->
<!--met:                                                                     -->
<!--                                                                         -->
<!--1. Redistributions of source code must retain the above copyright notice,-->
<!--   this list of conditions and the following disclaimer.                 -->
<!--                                                                         -->
<!--2. Redistributions in binary form must reproduce the above copyright     -->
<!--   notice, this list of conditions and the following disclaimer in the   -->
<!--   documentation and/or other materials provided with the distribution.  -->
<!--                                                                         -->
<!--THIS SOFTWARE IS PROVIDED BY THE COPYRIGHT HOLDERS AND CONTRIBUTORS "AS  -->
<!--IS" AND ANY EXPRESS OR IMPLIED WARRANTIES, INCLUDING, BUT NOT LIMITED TO,-->
<!--THE IMPLIED WARRANTIES OF MERCHANTABILITY AND FITNESS FOR A PARTICULAR   -->
<!--PURPOSE ARE DISCLAIMED. IN NO EVENT SHALL THE COPYRIGHT HOLDER OR        -->
<!--CONTRIBUTORS BE LIABLE FOR ANY DIRECT, INDIRECT, INCIDENTAL, SPECIAL,    -->
<!--EXEMPLARY, OR CONSEQUENTIAL DAMAGES (INCLUDING, BUT NOT LIMITED TO,      -->
<!--PROCUREMENT OF SUBSTITUTE GOODS OR SERVICES; LOSS OF USE, DATA, OR       -->
<!--PROFITS; OR BUSINESS INTERRUPTION) HOWEVER CAUSED AND ON ANY THEORY OF   -->
<!--LIABILITY, WHETHER IN CONTRACT, STRICT LIABILITY, OR TORT (INCLUDING     -->
<!--NEGLIGENCE OR OTHERWISE) ARISING IN ANY WAY OUT OF THE USE OF THIS       -->
<!--SOFTWARE, EVEN IF ADVISED OF THE POSSIBILITY OF SUCH DAMAGE.             -->
<robot name="lbr_iiwa">
    <!-- Import Rviz colors -->
    <material name="Grey">
        <color rgba="0.2 0.2 0.2 1.0"/>
    </material>
    <material name="Orange">
        <color rgba="1.0 0.423529411765 0.0392156862745 1.0"/>
    </material>
    <material name="Blue">
        <color rgba="0.5 0.7 1.0 1.0"/>
    </material>

    <!--Import the lbr iiwa macro -->
    <!--Import Transmissions -->
    <!--Include Utilities -->
    <!--The following macros are adapted from the LWR 4 definitions of the RCPRG - https://github.com/RCPRG-ros-pkg/lwr_robot -->
    <!--Little helper macros to define the inertia matrix needed for links.-->
    <!--Cuboid-->
    <!--Cylinder: length is along the y-axis! -->
    <!--lbr-->
    <link name="lbr_iiwa_link_0">
        <inertial>
            <origin rpy="0 0 0" xyz="-0.1 0 0.07"/>
            <!--Increase mass from 5 Kg original to provide a stable base to carry the
                arm.-->
            <mass value="0.0"/>
            <inertia ixx="0.05" ixy="0" ixz="0" iyy="0.06" iyz="0" izz="0.03"/>
        </inertial>
        <visual>
            <origin rpy="0 0 0" xyz="0 0 0"/>
            <geometry>
                <mesh filename="package://meshes/visual/link_0.obj"/>
            </geometry>
            <material name="Grey"/>
        </visual>
        <collision>
            <origin rpy="0 0 0" xyz="0 0 0"/>
            <geometry>
                <mesh filename="package://meshes/collision/link_0.stl"/>
            </geometry>
        </collision>
    </link>
    <!-- joint between link_0 and link_1 -->
    <joint name="lbr_iiwa_joint_1" type="revolute">
        <parent link="lbr_iiwa_link_0"/>
        <child link="lbr_iiwa_link_1"/>
        <origin rpy="0 0 0" xyz="0 0 0.1575"/>
        <axis xyz="0 0 1"/>
        <limit effort="300" lower="-2.96705972839" upper="2.96705972839" velocity="10"/>
        <dynamics damping="0.5"/>
    </joint>
    <link name="lbr_iiwa_link_1">
        <inertial>
            <origin rpy="0 0 0" xyz="0 -0.03 0.12"/>
            <mass value="4"/>
            <inertia ixx="0.1" ixy="0" ixz="0" iyy="0.09" iyz="0" izz="0.02"/>
        </inertial>
        <visual>
            <origin rpy="0 0 0" xyz="0 0 0"/>
            <geometry>
                <mesh filename="package://meshes/visual/link_1.obj"/>
            </geometry>
            <material name="Blue"/>
        </visual>
        <collision>
            <origin rpy="0 0 0" xyz="0 0 0"/>
            <geometry>
                <mesh filename="package://meshes/collision/link_1.stl"/>
            </geometry>
        </collision>
    </link>
    <!-- joint between link_1 and link_2 -->
    <joint name="lbr_iiwa_joint_2" type="revolute">
        <parent link="lbr_iiwa_link_1"/>
        <child link="lbr_iiwa_link_2"/>
        <origin rpy="1.57079632679   0 3.14159265359" xyz="0 0 0.2025"/>
        <axis xyz="0 0 1"/>
        <limit effort="300" lower="-2.09439510239" upper="2.09439510239" velocity="10"/>
        <dynamics damping="0.5"/>
    </joint>
    <link name="lbr_iiwa_link_2">
        <inertial>
            <origin rpy="0 0 0" xyz="0.0003 0.059 0.042"/>
            <mass value="4"/>
            <inertia ixx="0.05" ixy="0" ixz="0" iyy="0.018" iyz="0" izz="0.044"/>
        </inertial>
        <visual>
            <origin rpy="0 0 0" xyz="0 0 0"/>
            <geometry>
                <mesh filename="package://meshes/visual/link_2.obj"/>
            </geometry>
            <material name="Blue"/>
        </visual>
        <collision>
            <origin rpy="0 0 0" xyz="0 0 0"/>
            <geometry>
                <mesh filename="package://meshes/collision/link_2.stl"/>
            </geometry>
        </collision>
    </link>
    <!-- joint between link_2 and link_3 -->
    <joint name="lbr_iiwa_joint_3" type="revolute">
        <parent link="lbr_iiwa_link_2"/>
        <child link="lbr_iiwa_link_3"/>
        <origin rpy="1.57079632679 0 3.14159265359" xyz="0 0.2045 0"/>
        <axis xyz="0 0 1"/>
        <limit effort="300" lower="-2.96705972839" upper="2.96705972839" velocity="10"/>
        <dynamics damping="0.5"/>
    </joint>
    <link name="lbr_iiwa_link_3">
        <inertial>
            <origin rpy="0 0 0" xyz="0 0.03 0.13"/>
            <mass value="3"/>
            <inertia ixx="0.08" ixy="0" ixz="0" iyy="0.075" iyz="0" izz="0.01"/>
        </inertial>
        <visual>
            <origin rpy="0 0 0" xyz="0 0 0"/>
            <geometry>
                <mesh filename="package://meshes/visual/link_3.obj"/>
            </geometry>
            <material name="Orange"/>
        </visual>
        <collision>
            <origin rpy="0 0 0" xyz="0 0 0"/>
            <geometry>
                <mesh filename="package://meshes/collision/link_3.stl"/>
            </geometry>
        </collision>
    </link>
    <!-- joint between link_3 and link_4 -->
    <joint name="lbr_iiwa_joint_4" type="revolute">
        <parent link="lbr_iiwa_link_3"/>
        <child link="lbr_iiwa_link_4"/>
        <origin rpy="1.57079632679 0 0" xyz="0 0 0.2155"/>
        <axis xyz="0 0 1"/>
        <limit effort="300" lower="-2.09439510239" upper="2.09439510239" velocity="10"/>
        <dynamics damping="0.5"/>
    </joint>
    <link name="lbr_iiwa_link_4">
        <inertial>
            <origin rpy="0 0 0" xyz="0 0.067 0.034"/>
            <mass value="2.7"/>
            <inertia ixx="0.03" ixy="0" ixz="0" iyy="0.01" iyz="0" izz="0.029"/>
        </inertial>
        <visual>
            <origin rpy="0 0 0" xyz="0 0 0"/>
            <geometry>
                <mesh filename="package://meshes/visual/link_4.obj"/>
            </geometry>
            <material name="Blue"/>
        </visual>
        <collision>
            <origin rpy="0 0 0" xyz="0 0 0"/>
            <geometry>
                <mesh filename="package://meshes/collision/link_4.stl"/>
            </geometry>
        </collision>
    </link>
    <!-- joint between link_4 and link_5 -->
    <joint name="lbr_iiwa_joint_5" type="revolute">
        <parent link="lbr_iiwa_link_4"/>
        <child link="lbr_iiwa_link_5"/>
        <origin rpy="-1.57079632679 3.14159265359 0" xyz="0 0.1845 0"/>
        <axis xyz="0 0 1"/>
        <limit effort="300" lower="-2.96705972839" upper="2.96705972839" velocity="10"/>
        <dynamics damping="0.5"/>
    </joint>
    <link name="lbr_iiwa_link_5">
        <inertial>
            <origin rpy="0 0 0" xyz="0.0001 0.021 0.076"/>
            <mass value="1.7"/>
            <inertia ixx="0.02" ixy="0" ixz="0" iyy="0.018" iyz="0" izz="0.005"/>
        </inertial>
        <visual>
            <origin rpy="0 0 0" xyz="0 0 0"/>
            <geometry>
                <mesh filename="package://meshes/visual/link_5.obj"/>
            </geometry>
            <material name="Blue"/>
        </visual>
        <collision>
            <origin rpy="0 0 0" xyz="0 0 0"/>
            <geometry>
                <mesh filename="package://meshes/collision/link_5.stl"/>
            </geometry>
        </collision>
    </link>
    <!-- joint between link_5 and link_6 -->
    <joint name="lbr_iiwa_joint_6" type="revolute">
        <parent link="lbr_iiwa_link_5"/>
        <child link="lbr_iiwa_link_6"/>
        <origin rpy="1.57079632679 0 0" xyz="0 0 0.2155"/>
        <axis xyz="0 0 1"/>
        <limit effort="300" lower="-2.09439510239" upper="2.09439510239" velocity="10"/>
        <dynamics damping="0.5"/>
    </joint>
    <link name="lbr_iiwa_link_6">
        <inertial>
            <origin rpy="0 0 0" xyz="0 0.0006 0.0004"/>
            <mass value="1.8"/>
            <inertia ixx="0.005" ixy="0" ixz="0" iyy="0.0036" iyz="0" izz="0.0047"/>
        </inertial>
        <visual>
            <origin rpy="0 0 0" xyz="0 0 0"/>
            <geometry>
                <mesh filename="package://meshes/visual/link_6.obj"/>
            </geometry>
            <material name="Orange"/>
        </visual>
        <collision>
            <origin rpy="0 0 0" xyz="0 0 0"/>
            <geometry>
                <mesh filename="package://meshes/collision/link_6.stl"/>
            </geometry>
        </collision>
    </link>
    <!-- joint between link_6 and link_7 -->
    <joint name="lbr_iiwa_joint_7" type="revolute">
        <parent link="lbr_iiwa_link_6"/>
        <child link="lbr_iiwa_link_7"/>
        <origin rpy="-1.57079632679 3.14159265359 0" xyz="0 0.081 0"/>
        <axis xyz="0 0 1"/>
        <limit effort="300" lower="-3.05432619099" upper="3.05432619099" velocity="10"/>
        <dynamics damping="0.5"/>
    </joint>
    <link name="lbr_iiwa_link_7">
        <inertial>
            <origin rpy="0 0 0" xyz="0 0 0.02"/>
            <mass value="0.3"/>
            <inertia ixx="0.001" ixy="0" ixz="0" iyy="0.001" iyz="0" izz="0.001"/>
        </inertial>
        <visual>
            <origin rpy="0 0 0" xyz="0 0 0"/>
            <geometry>
                <mesh filename="package://meshes/visual/link_7.obj"/>
            </geometry>
            <material name="Grey"/>
        </visual>
        <collision>
            <origin rpy="0 0 0" xyz="0 0 0"/>
            <geometry>
                <mesh filename="package://meshes/collision/link_7.stl"/>
            </geometry>
        </collision>
    </link>

    ## Robotiq 85 Gripper

    <joint name="arm_gripper_joint" type="fixed">
        <parent link="lbr_iiwa_link_7"/>
        <child link="robotiq_85_base_link"/>
        <origin rpy="0.0 0.0 0.0" xyz="0.0 0.0 0.0111"/>
<!--        <origin rpy="-1.570796 3.141592 0.0" xyz="0.0 0.0823 0.0"/>-->
        <axis xyz="1 0 0"/>
    </joint>

    <link name="robotiq_85_base_link">
        <inertial>
            <origin xyz="0.00021987 -2.3546E-10 0.030163" rpy="0 0 0"/>
            <mass value="0.30915"/>
            <inertia ixx="0.00028972" ixy="-5.7879E-10" ixz="-1.8543E-06"
                     iyy="0.00030737" iyz="1.682E-12" izz="0.00019914"/>
        </inertial>
        <visual>
            <origin xyz="0 0 0" rpy="0 0 0"/>
            <geometry>
                <mesh filename="package://meshes/visual/robotiq_85_base_link_fine.STL"/>
            </geometry>
            <material name="dark-grey">
                <color rgba=".16 .16 .16 1"/>
            </material>
        </visual>
        <collision>
            <origin xyz="0 0 0" rpy="0 0 0"/>
            <geometry>
                <mesh filename="package://meshes/collision/robotiq_85_base_link_coarse.STL"/>
            </geometry>
        </collision>
    </link>
    <link name="left_inner_finger">
        <inertial>
            <origin xyz="0.0060275613594574 -6.29183141465421E-15 0.00669925693133241"
                    rpy="0 0 0"/>
            <mass value="0.00724255346165745"/>
            <inertia
                    ixx="1.47824274053603E-06"
                    ixy="-3.94884463570303E-19"
                    ixz="-3.45268847648622E-07"
                    iyy="1.70064480838395E-06"
                    iyz="3.5059838910097E-19"
                    izz="4.77151336838364E-07"/>
        </inertial>
        <visual>
            <origin xyz="0 0 0"
                    rpy="0 0 0"/>
            <geometry>
                <mesh filename="package://meshes/visual/inner_finger_fine.STL"/>
            </geometry>
            <material name="dark-grey">
                <color rgba=".16 .16 .16 1"/>
            </material>
        </visual>
        <collision>
            <origin xyz="0 0 0"
                    rpy="0 0 0"/>
            <geometry>
                <mesh filename="package://meshes/collision/inner_finger_coarse.STL"/>
            </geometry>
        </collision>
        <contact>
            <stiffness value="10000"/>
            <damping value="10"/>
            <lateral_friction value="100.0"/>

        </contact>

    </link>
    <joint name="left_inner_finger_joint" type="prismatic">
        <!--        <origin xyz="0.034585310861294 0 0.0454970193817975" rpy="0 0 0"/>-->
        <!--        <parent link="left_inner_knuckle"/>-->
        <parent link="robotiq_85_base_link"/>
        <child link="left_inner_finger"/>
        <origin xyz="0.0064 0 0.126" rpy="0 0 0"/>
        <axis xyz="0.95307293 0. -0.30274081"/>
        <limit lower="0." upper=".0425" velocity="0.1" effort="10"/>
        <!--        <axis xyz="0 -1 0"/>-->
        <!--        <limit lower="-.0425" upper="0" velocity="2.0" effort="20"/>-->
    </joint>
    <link name="right_inner_finger">
        <inertial>
            <origin xyz="0.00602756228812038 -6.47284509480176E-15 0.00669925609578108"
                    rpy="0 0 0"/>
            <mass value="0.00724255346165744"/>
            <inertia
                    ixx="1.47824283625957E-06"
                    ixy="-3.95952064019123E-19"
                    ixz="-3.45268708875543E-07"
                    iyy="1.70064480838394E-06"
                    iyz="3.55286507960029E-19"
                    izz="4.77151241114822E-07"/>
        </inertial>
        <visual>
            <origin xyz="0 0 0" rpy="0 0 0"/>
            <geometry>
                <mesh filename="package://meshes/visual/inner_finger_fine.STL"/>
            </geometry>
            <material name="dark-grey">
                <color rgba=".16 .16 .16 1"/>
            </material>
        </visual>
        <collision>
            <origin xyz="0 0 0"
                    rpy="0 0 0"/>
            <geometry>
                <mesh filename="package://meshes/collision/inner_finger_coarse.STL"/>
            </geometry>
        </collision>
        <contact>
            <stiffness value="10000"/>
            <damping value="10"/>
            <lateral_friction value="100.0"/>

        </contact>

    </link>

    <joint name="right_inner_finger_joint" type="prismatic">
        <parent link="robotiq_85_base_link"/>
        <child link="right_inner_finger"/>
        <origin xyz="-0.0064 0 0.126" rpy="0 0 3.1416"/>
        <axis xyz="0.95307293 0. -0.30274081"/>
        <limit lower="0." upper=".0425" velocity="0.1" effort="10"/>
    </joint>

    <joint name="tcp" type="fixed">
        <parent link="robotiq_85_base_link"/>
        <child link="tcp"/>
        <origin rpy="3.14159 0 -1.570796" xyz="0.0 0.0 0.15"/>
        <axis xyz="0 1 0"/>
    </joint>

    <link name="tcp">
        <inertial>
            <mass value="0.0"/>
            <inertia ixx="1.0" ixy="1.0" ixz="1.0" iyy="0.0" iyz="0.0"
                     izz="0.0"/>
        </inertial>
    </link>

    <klampt package_root="." freeze_root_link="1"/>

</robot>

